<?xml version="1.0" encoding="UTF-8"?>
<sdf version='1.9'>
  <model name='x500_base'>
    <pose>0 0 .24 0 0 0</pose>
    <self_collide>false</self_collide>
    <static>false</static>

   <link name='base_link'>
      <pose frame=''>0 0 0 0 -0 0</pose>
      <inertial>
        <pose frame=''>0.001005 0 -0.0090035 0 -0 0</pose>
        <mass>2.02</mass>
        <inertia>
          <ixx>0.011</ixx>
          <ixy>0</ixy>
          <ixz>0</ixz>
          <iyy>0.015</iyy>
          <iyz>0</iyz>
          <izz>0.021</izz>
        </inertia>
      </inertial>
       <gravity>true</gravity>
      <velocity_decay />
      <collision name='base_link_collision'>
        <pose frame=''>0 0 0.0 0 0 0</pose>
        <geometry>
          <box>
            <size>0.67 0.67 0.15</size>
          </box>
        </geometry>
        <surface>
          <contact>
            <ode>
              <min_depth>0.001</min_depth>
              <max_vel>0</max_vel>
            </ode>
          </contact>
          <friction>
            <ode/>
          </friction>
        </surface>
      </collision>

      <sensor name="air_pressure_sensor" type="air_pressure">
        <gz_frame_id>base_link</gz_frame_id>
        <always_on>1</always_on>
        <update_rate>50</update_rate>
        <air_pressure>
          <pressure>
            <noise type="gaussian">
              <mean>0</mean>
              <stddev>3</stddev>
            </noise>
          </pressure>
        </air_pressure>
      </sensor>
      <sensor name="magnetometer_sensor" type="magnetometer">
        <gz_frame_id>base_link</gz_frame_id>
        <always_on>1</always_on>
        <update_rate>100</update_rate>
        <magnetometer>
          <x>
            <noise type="gaussian">
              <stddev>0.0001</stddev>
            </noise>
          </x>
          <y>
            <noise type="gaussian">
              <stddev>0.0001</stddev>
            </noise>
          </y>
          <z>
            <noise type="gaussian">
              <stddev>0.0001</stddev>
            </noise>
          </z>
        </magnetometer>
      </sensor>
      <sensor name="imu_sensor" type="imu">
        <gz_frame_id>base_link</gz_frame_id>
        <always_on>1</always_on>
        <update_rate>250</update_rate>
        <imu>
          <angular_velocity>
            <x>
              <noise type="gaussian">
                <mean>0.0</mean>
                <stddev>0.0008726646</stddev>
              </noise>
            </x>
            <y>
              <noise type="gaussian">
                <mean>0.0</mean>
                <stddev>0.0008726646</stddev>
              </noise>
            </y>
            <z>
              <noise type="gaussian">
                <mean>0.0</mean>
                <stddev>0.0008726646</stddev>
              </noise>
            </z>
          </angular_velocity>
          <linear_acceleration>
            <x>
              <noise type="gaussian">
                <mean>0.0</mean>
                <stddev>0.00637</stddev>
              </noise>
            </x>
            <y>
              <noise type="gaussian">
                <mean>0.0</mean>
                <stddev>0.00637</stddev>
              </noise>
            </y>
            <z>
              <noise type="gaussian">
                <mean>0.0</mean>
                <stddev>0.00686</stddev>
              </noise>
            </z>
          </linear_acceleration>
        </imu>
      </sensor>
      <sensor name="navsat_sensor" type="navsat">
        <gz_frame_id>base_link</gz_frame_id>
        <always_on>1</always_on>
        <update_rate>30</update_rate>
      </sensor>

      <visual name='base_link_visual'>
        <pose frame=''>0 0 0 0 -0 0</pose>
        <geometry>
          <mesh>
            <scale>0.001 0.001 0.001</scale>
        <uri>model://x500_base/meshes/main_body_remeshed_v3.stl</uri>
          </mesh>
        </geometry>
        <material>
          <diffuse>1 0 0 1</diffuse>
          <script>
              <name>Gazebo/Black</name>
              <uri>file://media/materials/scripts/gazebo.material</uri>
          </script>
        </material>
      </visual>
      <gravity>1</gravity>
      <velocity_decay/>
      <self_collide>0</self_collide>
    </link>

    <link name="cgo3_mount_link">
      <inertial>
        <pose>-0.041 0 -0.162 0 0 0</pose>
        <mass>0.1</mass>
        <inertia>
          <ixx>0.001</ixx><iyy>0.001</iyy><izz>0.001</izz>
          <ixy>0</ixy><ixz>0</ixz><iyz>0</iyz>
        </inertia>
      </inertial>
      <visual name='cgo3_mount_visual'>
        <geometry>
          <mesh>
            <scale>0.001 0.001 0.001</scale>
            <uri>model://x500_base/meshes/cgo3_mount_remeshed_v1.stl</uri>
          </mesh>
        </geometry>
        <material>
          <script>
            <name>Gazebo/DarkGrey</name>
            <uri>file://media/materials/scripts/gazebo.material</uri>
          </script>
        </material>
      </visual>
    </link>

    <joint name='cgo3_mount_joint' type='revolute'>
      <child>cgo3_mount_link</child>
      <parent>base_link</parent>
      <axis>
        <xyz>0 0 1</xyz>
        <limit><lower>0</lower><upper>0</upper></limit>
      </axis>
    </joint>

    <link name="cgo3_vertical_arm_link">
      <inertial>
        <pose>-0.041 0 -0.162 0 0 0</pose>
        <mass>0.1</mass>
        <inertia>
          <ixx>0.001</ixx><iyy>0.001</iyy><izz>0.001</izz>
        </inertia>
      </inertial>
      <visual name='cgo3_vertical_arm_visual'>
        <pose>-0.051 0 0 0 0 3.141592</pose>
        <geometry>
          <mesh>
            <scale>0.001 0.001 0.001</scale>
            <uri>model://x500_base/meshes/cgo3_vertical_arm_remeshed_v1.stl</uri>
          </mesh>
        </geometry>
        <material>
          <script>
            <name>Gazebo/DarkGrey</name>
            <uri>file://media/materials/scripts/gazebo.material</uri>
          </script>
        </material>
      </visual>
    </link>

    <joint name='cgo3_vertical_arm_joint' type='revolute'>
      <child>cgo3_vertical_arm_link</child>
      <parent>cgo3_mount_link</parent>
      <pose>-0.026 0 -0.10 0 0 0</pose>
      <axis>
        <xyz>0 0 1</xyz>
        <limit>
          <lower>-3.14159</lower>
          <upper>3.14159</upper>
          <effort>100</effort>
          <velocity>1.0</velocity>
        </limit>
      </axis>
    </joint>

    <link name="cgo3_horizontal_arm_link">
      <inertial>
        <pose>-0.041 0 -0.081 0 0 0</pose>
        <mass>0.1</mass>
        <inertia>
          <ixx>0.001</ixx><iyy>0.001</iyy><izz>0.001</izz>
        </inertia>
      </inertial>
      <visual name='cgo3_horizontal_arm_visual'>
        <pose>-0.05 0 0 0 0 3.141592</pose>
        <geometry>
          <mesh>
            <scale>0.001 0.001 0.001</scale>
            <uri>model://x500_base/meshes/cgo3_horizontal_arm_remeshed_v1.stl</uri>
          </mesh>
        </geometry>
        <material>
          <script>
            <name>Gazebo/DarkGrey</name>
            <uri>file://media/materials/scripts/gazebo.material</uri>
          </script>
        </material>
      </visual>
    </link>

    <joint name='cgo3_horizontal_arm_joint' type='revolute'>
      <child>cgo3_horizontal_arm_link</child>
      <parent>cgo3_vertical_arm_link</parent>
      <pose>-0.07 0 -0.162 0 0 0</pose>
      <axis>
        <xyz>-1 0 0</xyz>
        <limit>
          <lower>-0.785398</lower>
          <upper>0.785398</upper>
          <effort>100</effort>
          <velocity>1.0</velocity>
        </limit>
      </axis>
    </joint>

    <link name="cgo3_camera_link">
      <inertial>
        <pose>-0.041 0 -0.162 0 0 0</pose>
        <mass>0.1</mass>
        <inertia>
          <ixx>0.001</ixx><iyy>0.001</iyy><izz>0.001</izz>
        </inertia>
      </inertial>
      <visual name='cgo3_camera_visual'>
        <pose>-0.05 0 0 0 0 3.141592</pose>
        <geometry>
          <mesh>
            <scale>0.001 0.001 0.001</scale>
            <uri>model://x500_base/meshes/cgo3_camera_remeshed_v1.stl</uri>
          </mesh>
        </geometry>
        <material>
          <script>
            <name>Gazebo/DarkGrey</name>
            <uri>file://media/materials/scripts/gazebo.material</uri>
          </script>
        </material>
      </visual>

      <sensor name="camera" type="camera">
        <pose>0.0 0 -0.162 0 0.785 0</pose>
        <camera>
          <horizontal_fov>2.0</horizontal_fov>
          <image>
            <format>R8G8B8</format>
            <width>640</width>
            <height>360</height>
          </image>
          <clip>
            <near>0.05</near>
            <far>15000</far>
          </clip>
        </camera>
        <always_on>1</always_on>
        <update_rate>30</update_rate>
        <visualize>true</visualize>
      </sensor>
    </link>

    <joint name='cgo3_camera_joint' type='fixed'>
      <child>cgo3_camera_link</child>
      <parent>cgo3_horizontal_arm_link</parent>
      <pose>-0.01 0.03 -0.162 0 0 0</pose>
      <axis>
        <xyz>0 -1 0</xyz>
        <limit>
          <lower>-1.5708</lower>
          <upper>0.7854</upper>
          <effort>100</effort>
          <velocity>1.0</velocity>
        </limit>
      </axis>
    </joint>

    <plugin
      filename="gz-sim-joint-position-controller-system"
      name="gz::sim::systems::JointPositionController">
      <joint_name>cgo3_vertical_arm_joint</joint_name>
      <p_gain>5.0</p_gain>
      <i_gain>0.05</i_gain>
      <d_gain>0.1</d_gain>
    </plugin>

    <plugin
      filename="gz-sim-joint-position-controller-system"
      name="gz::sim::systems::JointPositionController">
      <joint_name>cgo3_horizontal_arm_joint</joint_name>
      <p_gain>5.0</p_gain>
      <i_gain>0.05</i_gain>
      <d_gain>0.1</d_gain>
    </plugin>

  
    <link name="left_leg">
      <inertial>
        <pose>0 -0.14314 -0.207252 0 0 0</pose>
        <mass>0.1</mass>
        <inertia>
          <ixx>0.001</ixx>
          <ixy>0</ixy>
          <ixz>0</ixz>
          <iyy>0.001</iyy>
          <iyz>0</iyz>
          <izz>0.001</izz>
        </inertia>
      </inertial>
      <collision name='collision'>
        <pose>-0.005 -0.14314 -0.207252 0 1.56893 0</pose>
        <geometry>
          <cylinder>
            <radius>0.012209</radius>
            <length>0.3</length>
          </cylinder>
        </geometry>
        <surface>
          <friction>
            <ode>
              <mu>1</mu>
              <mu2>1</mu2>
            </ode>
          </friction>
          <contact>
            <ode>
              <kp>1e+8</kp>
              <kd>1</kd>
              <max_vel>0.01</max_vel>
              <min_depth>0.001</min_depth>
            </ode>
          </contact>
        </surface>
      </collision>
      <collision name='collision_bar'>
        <pose>0.00052 -0.08503 -0.121187 -0.501318 0 0</pose>
        <geometry>
          <cylinder>
            <radius>0.00914984</radius>
            <length>0.176893</length>
          </cylinder>
        </geometry>
        <surface>
          <friction>
            <ode>
              <mu>1</mu>
              <mu2>1</mu2>
            </ode>
          </friction>
          <contact>
            <ode>
              <kp>1e+8</kp>
              <kd>1</kd>
              <max_vel>0.01</max_vel>
              <min_depth>0.001</min_depth>
            </ode>
          </contact>
        </surface>
      </collision>
      <visual name='base_link_left_leg'>
        <pose>0 0 0 0 0 0</pose>
        <geometry>
          <mesh>
            <scale>0.001 0.001 0.001</scale>
            <uri>model://x500_base/meshes/leg2_remeshed_v3.stl</uri>
          </mesh>
        </geometry>
        <material>
          <script>
            <name>Gazebo/Black</name>
            <uri>file://media/materials/scripts/gazebo.material</uri>
          </script>
        </material>
      </visual>
    </link>

    <joint name='left_leg_joint' type='fixed'>
      <child>left_leg</child>
      <parent>base_link</parent>
      <pose>0.00026 -0.040515 -0.048 0 0 0</pose>
      <axis>
        <xyz>-1 0 0</xyz>
        <limit>
          <lower>0</lower>
          <upper>1</upper>
          <effort>100</effort>
          <velocity>-1</velocity>
          <stiffness>100000000</stiffness>
          <dissipation>1</dissipation>
        </limit>
        <dynamics>
          <damping>0.1</damping>
        </dynamics>
        <use_parent_model_frame>1</use_parent_model_frame>
      </axis>
      <physics>
        <ode>
          <implicit_spring_damper>1</implicit_spring_damper>
        </ode>
      </physics>
    </joint>

    <link name="right_leg">
      <pose>0 0 0 0 0 0</pose>
      <inertial>
        <pose>0 0.14314 -0.207252 0 0 0</pose>
        <mass>0.1</mass>
        <inertia>
          <ixx>0.001</ixx>
          <ixy>0</ixy>
          <ixz>0</ixz>
          <iyy>0.001</iyy>
          <iyz>0</iyz>
          <izz>0.001</izz>
        </inertia>
      </inertial>
      <collision name='collision'>
        <pose>-0.005 0.14314 -0.207252 0 1.56893 0</pose>
        <geometry>
          <cylinder>
            <radius>0.012209</radius>
            <length>0.3</length>
          </cylinder>
        </geometry>
        <surface>
          <friction>
            <ode>
              <mu>1</mu>
              <mu2>1</mu2>
            </ode>
          </friction>
          <contact>
            <ode>
              <kp>1e+8</kp>
              <kd>1</kd>
              <max_vel>0.01</max_vel>
              <min_depth>0.001</min_depth>
            </ode>
          </contact>
        </surface>
      </collision>
      <collision name='collision_bar'>
        <pose>0.00052 0.08503 -0.121187 0.501318 0 0</pose>
        <geometry>
          <cylinder>
            <radius>0.00914984</radius>
            <length>0.176893</length>
          </cylinder>
        </geometry>
        <surface>
          <friction>
            <ode>
              <mu>1</mu>
              <mu2>1</mu2>
            </ode>
          </friction>
          <contact>
            <ode>
              <kp>1e+8</kp>
              <kd>1</kd>
              <max_vel>0.01</max_vel>
              <min_depth>0.001</min_depth>
            </ode>
          </contact>
        </surface>
      </collision>
      <visual name='base_link_right_leg'>
        <pose>0 0 0 0 0 0</pose>
        <geometry>
          <mesh>
            <scale>0.001 0.001 0.001</scale>
            <uri>model://x500_base/meshes/leg1_remeshed_v3.stl</uri>
          </mesh>
        </geometry>
        <material>
          <script>
            <name>Gazebo/Black</name>
            <uri>file://media/materials/scripts/gazebo.material</uri>
          </script>
        </material>
      </visual>
    </link>

    <joint name='right_leg_joint' type='fixed'>
      <child>right_leg</child>
      <parent>base_link</parent>
      <pose>0.00026 0.040515 -0.048 0 0 0</pose>
      <axis>
        <xyz>1 0 0</xyz>
        <limit>
          <lower>0</lower>
          <upper>1</upper>
          <effort>100</effort>
          <velocity>-1</velocity>
          <stiffness>100000000</stiffness>
          <dissipation>1</dissipation>
        </limit>
        <dynamics>
          <damping>0.1</damping>
        </dynamics>
        <use_parent_model_frame>1</use_parent_model_frame>
      </axis>
      <physics>
        <ode>
          <implicit_spring_damper>1</implicit_spring_damper>
        </ode>
      </physics>
    </joint>

    <link name='rotor_3'>
      <pose frame=''>0.211396 0.119762 0.082219 0 0 0</pose>
      <inertial>
        <pose frame=''>0 0 0 0 -0 0</pose>
        <mass>0.005</mass>
        <inertia>
          <ixx>9.75e-07</ixx>
          <ixy>0</ixy>
          <ixz>0</ixz>
          <iyy>0.000273104</iyy>
          <iyz>0</iyz>
          <izz>0.000274004</izz>
        </inertia>
      </inertial>
      <collision name='rotor_3_collision'>
        <pose frame=''>0 0 0 0 -0 0</pose>
        <geometry>
          <cylinder>
            <length>0.005</length>
            <radius>0.128</radius>
          </cylinder>
        </geometry>
      </collision>
      <visual name='rotor_3_visual'>
        <pose frame=''>-0.211396 -0.119762 -0.082219 0 0 0</pose>
        <geometry>
          <mesh>
            <scale>0.001 0.001 0.001</scale>
            <uri>model://x500_base/meshes/prop_ccw_assembly_remeshed_v3.stl</uri>
          </mesh>
        </geometry>
        <material>
          <diffuse>1 0 0 1</diffuse>
          <script>
            <name>Gazebo/Blue</name>
            <uri>file://media/materials/scripts/gazebo.material</uri>
          </script>
        </material>
      </visual>
      <gravity>1</gravity>
      <velocity_decay/>
      <self_collide>0</self_collide>
    </link>

    <joint name='rotor_3_joint' type='revolute'>
      <child>rotor_3</child>
      <parent>base_link</parent>
      <axis>
        <xyz>0.0446 -0.0825 1.8977</xyz>
        <limit>
          <lower>-1e+16</lower>
          <upper>1e+16</upper>
          <effort>10</effort>
          <velocity>-1</velocity>
        </limit>
        <dynamics>
          <damping>0.005</damping>
        </dynamics>
        <use_parent_model_frame>1</use_parent_model_frame>
      </axis>
      <physics>
        <ode>
          <implicit_spring_damper>1</implicit_spring_damper>
        </ode>
      </physics>
    </joint>

    <link name='rotor_0'>
      <pose frame=''>-0.209396 0.122762 0.082219 0 0 2.09439510239</pose>
      <inertial>
        <pose frame=''>0 0 0 0 -0 0</pose>
        <mass>0.005</mass>
        <inertia>
          <ixx>9.75e-07</ixx>
          <ixy>0</ixy>
          <ixz>0</ixz>
          <iyy>0.000273104</iyy>
          <iyz>0</iyz>
          <izz>0.000274004</izz>
        </inertia>
      </inertial>
      <collision name='rotor_0_collision'>
        <pose frame=''>0 0 0 0 -0 0</pose>
        <geometry>
          <cylinder>
            <length>0.005</length>
            <radius>0.128</radius>
          </cylinder>
        </geometry>
      </collision>
      <visual name='rotor_0_visual'>
        <pose frame=''>-0.211396 -0.119762 -0.082219 0 0 0</pose>
        <geometry>
          <mesh>
            <scale>0.001 0.001 0.001</scale>
            <uri>model://x500_base/meshes/prop_ccw_assembly_remeshed_v3.stl</uri>
          </mesh>
        </geometry>
        <material>
          <diffuse>0 0 1 1</diffuse>
          <script>
            <name>Gazebo/Blue</name>
            <uri>file://media/materials/scripts/gazebo.material</uri>
          </script>
        </material>
      </visual>
      <gravity>1</gravity>
      <velocity_decay/>
      <self_collide>0</self_collide>
    </link>

    <joint name='rotor_0_joint' type='revolute'>
      <child>rotor_0</child>
      <parent>base_link</parent>
      <axis>
        <xyz>0.046 0.0827 1.8977</xyz>
        <limit>
          <lower>-1e+16</lower>
          <upper>1e+16</upper>
          <effort>10</effort>
          <velocity>-1</velocity>
        </limit>
        <dynamics>
          <damping>0.005</damping>
        </dynamics>
        <use_parent_model_frame>1</use_parent_model_frame>
      </axis>
      <physics>
        <ode>
          <implicit_spring_damper>1</implicit_spring_damper>
        </ode>
      </physics>
    </joint>

    <link name='rotor_4'>
      <pose frame=''>-0.00187896 0.242705 0.0822169 0 0 0</pose>
      <inertial>
        <pose frame=''>0 0 0 0 -0 0</pose>
        <mass>0.005</mass>
        <inertia>
          <ixx>9.75e-07</ixx>
          <ixy>0</ixy>
          <ixz>0</ixz>
          <iyy>0.000273104</iyy>
          <iyz>0</iyz>
          <izz>0.000274004</izz>
        </inertia>
      </inertial>
      <collision name='rotor_4_collision'>
        <pose frame=''>0 0 0 0 -0 0</pose>
        <geometry>
          <cylinder>
            <length>0.005</length>
            <radius>0.128</radius>
          </cylinder>
        </geometry>
      </collision>
      <visual name='rotor_4_visual'>
        <pose frame=''>0.00187896 -0.242705 -0.0822169 0 0 0</pose>
        <geometry>
          <mesh>
            <scale>0.001 0.001 0.001</scale>
            <uri>model://x500_base/meshes/prop_cw_assembly_remeshed_v3.stl</uri>
          </mesh>
        </geometry>
        <material>
          <diffuse>0 0 1 1</diffuse>
          <script>
            <name>Gazebo/Red</name>
            <uri>file://media/materials/scripts/gazebo.material</uri>
          </script>
        </material>
      </visual>
      <gravity>1</gravity>
      <velocity_decay/>
      <self_collide>0</self_collide>
    </link>

    <joint name='rotor_4_joint' type='revolute'>
      <child>rotor_4</child>
      <parent>base_link</parent>
      <axis>
        <xyz>-0.09563 -0.0003 1.8976</xyz>
        <limit>
          <lower>-1e+16</lower>
          <upper>1e+16</upper>
          <effort>10</effort>
          <velocity>-1</velocity>
        </limit>
        <dynamics>
          <damping>0.005</damping>
        </dynamics>
        <use_parent_model_frame>1</use_parent_model_frame>
      </axis>
      <physics>
        <ode>
          <implicit_spring_damper>1</implicit_spring_damper>
        </ode>
      </physics>
    </joint>

    <link name='rotor_1'>
      <pose frame=''>0.211396 -0.119762 0.082219 0 0 -2.09439510239</pose>
      <inertial>
        <pose frame=''>0 0 0 0 -0 0</pose>
        <mass>0.005</mass>
        <inertia>
          <ixx>9.75e-07</ixx>
          <ixy>0</ixy>
          <ixz>0</ixz>
          <iyy>0.000273104</iyy>
          <iyz>0</iyz>
          <izz>0.000274004</izz>
        </inertia>
      </inertial>
      <collision name='rotor_1_collision'>
        <pose frame=''>0 0 0 0 -0 0</pose>
        <geometry>
          <cylinder>
            <length>0.005</length>
            <radius>0.128</radius>
          </cylinder>
        </geometry>
      </collision>
      <visual name='rotor_1_visual'>
        <pose frame=''>0.00187896 -0.242705 -0.0822169 0 0 0</pose>
        <geometry>
          <mesh>
            <scale>0.001 0.001 0.001</scale>
            <uri>model://x500_base/meshes/prop_cw_assembly_remeshed_v3.stl</uri>
          </mesh>
        </geometry>
        <material>
          <diffuse>0 0 1 1</diffuse>
          <script>
            <name>Gazebo/Red</name>
            <uri>file://media/materials/scripts/gazebo.material</uri>
          </script>
        </material>
      </visual>
      <gravity>1</gravity>
      <velocity_decay/>
      <self_collide>0</self_collide>
    </link>

    <joint name='rotor_1_joint' type='revolute'>
      <child>rotor_1</child>
      <parent>base_link</parent>
      <axis>
        <xyz>0.0486 0.0811 1.8976</xyz>
        <limit>
          <lower>-1e+16</lower>
          <upper>1e+16</upper>
          <effort>10</effort>
          <velocity>-1</velocity>
        </limit>
        <dynamics>
          <damping>0.005</damping>
        </dynamics>
        <use_parent_model_frame>1</use_parent_model_frame>
      </axis>
      <physics>
        <ode>
          <implicit_spring_damper>1</implicit_spring_damper>
        </ode>
      </physics>
    </joint>

    <link name='rotor_5'>
      <pose frame=''>-0.00187896 -0.242705 0.0822169 0 0 -2.09439510239</pose>
      <inertial>
        <pose frame=''>0 0 0 0 -0 0</pose>
        <mass>0.005</mass>
        <inertia>
          <ixx>9.75e-07</ixx>
          <ixy>0</ixy>
          <ixz>0</ixz>
          <iyy>0.000273104</iyy>
          <iyz>0</iyz>
          <izz>0.000274004</izz>
        </inertia>
      </inertial>
      <collision name='rotor_5_collision'>
        <pose frame=''>0 0 0 0 -0 0</pose>
        <geometry>
          <cylinder>
            <length>0.005</length>
            <radius>0.128</radius>
          </cylinder>
        </geometry>
      </collision>
      <visual name='rotor_5_visual'>
        <pose frame=''>-0.211396 -0.119762 -0.082219 0 0 0</pose>
        <geometry>
          <mesh>
            <scale>0.001 0.001 0.001</scale>
            <uri>model://x500_base/meshes/prop_ccw_assembly_remeshed_v3.stl</uri>
          </mesh>
        </geometry>
        <material>
          <diffuse>0 0 1 1</diffuse>
          <script>
            <name>Gazebo/Blue</name>
            <uri>file://media/materials/scripts/gazebo.material</uri>
          </script>
        </material>
      </visual>
      <gravity>1</gravity>
      <velocity_decay/>
      <self_collide>0</self_collide>
    </link>

    <joint name='rotor_5_joint' type='revolute'>
      <child>rotor_5</child>
      <parent>base_link</parent>
      <axis>
        <xyz>-0.033996 -0.0006 0.68216</xyz>
        <limit>
          <lower>-1e+16</lower>
          <upper>1e+16</upper>
          <effort>10</effort>
          <velocity>-1</velocity>
        </limit>
        <dynamics>
          <damping>0.005</damping>
        </dynamics>
        <use_parent_model_frame>1</use_parent_model_frame>
      </axis>
      <physics>
        <ode>
          <implicit_spring_damper>1</implicit_spring_damper>
        </ode>
      </physics>
    </joint>

    <link name='rotor_2'>
      <pose frame=''>-0.209396 -0.122762 0.082219 0 0 2.09439510239</pose>
      <inertial>
        <pose frame=''>0 0 0 0 -0 0</pose>
        <mass>0.005</mass>
        <inertia>
          <ixx>9.75e-07</ixx>
          <ixy>0</ixy>
          <ixz>0</ixz>
          <iyy>0.000273104</iyy>
          <iyz>0</iyz>
          <izz>0.000274004</izz>
        </inertia>
      </inertial>
      <collision name='rotor_2_collision'>
        <pose frame=''>0 0 0 0 -0 0</pose>
        <geometry>
          <cylinder>
            <length>0.005</length>
            <radius>0.128</radius>
          </cylinder>
        </geometry>
      </collision>
      <visual name='rotor_2_visual'>
        <pose frame=''>0.00187896 -0.242705 -0.0822169 0 0 0</pose>
        <geometry>
          <mesh>
            <scale>0.001 0.001 0.001</scale>
            <uri>model://x500_base/meshes/prop_cw_assembly_remeshed_v3.stl</uri>
          </mesh>
        </geometry>
        <material>
          <diffuse>1 0 0 1</diffuse>
          <script>
            <name>Gazebo/Red</name>
            <uri>file://media/materials/scripts/gazebo.material</uri>
          </script>
        </material>
      </visual>
      <gravity>1</gravity>
      <velocity_decay/>
      <self_collide>0</self_collide>
    </link>

    <joint name='rotor_2_joint' type='revolute'>
      <child>rotor_2</child>
      <parent>base_link</parent>
      <axis>
        <xyz>0.0404 -0.0876 1.8976</xyz>
        <limit>
          <lower>-1e+16</lower>
          <upper>1e+16</upper>
          <effort>10</effort>
          <velocity>-1</velocity>
        </limit>
        <dynamics>
          <damping>0.005</damping>
        </dynamics>
        <use_parent_model_frame>1</use_parent_model_frame>
      </axis>
      <physics>
        <ode>
          <implicit_spring_damper>1</implicit_spring_damper>
        </ode>
      </physics>
    </joint>

  </model>
</sdf>
